Workbook

Sheet Painel
A1: TCDF / ANACE 2026 — acompanhamento por matéria
A2: Uma aba por matéria. Nesta folha, tudo é fórmula: os números se atualizam sozinhos conforme você preenche as abas. Meta: 90% bruto.
A4: Dia | B4: Matéria | C4: Tópicos | D4: Itens do edital | E4: Filtros vencidos | F4: Lotes registrados | G4: Melhor % bruto | H4: Último % bruto
A5: Segunda-feira | B5: Administração Financeira e Orçamentária | C5: 9 | D5: 15 | E5: =COUNTIF('AFO'!E5:L5,"S") | F5: =COUNT('AFO'!C49:C68) | G5: =IFERROR(MAX('AFO'!F49:F68),"") | H5: =IFERROR(INDEX('AFO'!F49:F68,COUNT('AFO'!C49:C68)),"")
A6: Segunda-feira | B6: Noções de Direito Tributário | C6: 3 | D6: 4 | E6: =COUNTIF('D. Tributário'!E5:L5,"S") | F6: =COUNT('D. Tributário'!C29:C48) | G6: =IFERROR(MAX('D. Tributário'!F29:F48),"") | H6: =IFERROR(INDEX('D. Tributário'!F29:F48,COUNT('D. Tributário'!C29:C48)),"")
A7: Terça-feira | B7: Direito Administrativo | C7: 14 | D7: 25 | E7: =COUNTIF('D. Administrativo'!E5:L5,"S") | F7: =COUNT('D. Administrativo'!C68:C87) | G7: =IFERROR(MAX('D. Administrativo'!F68:F87),"") | H7: =IFERROR(INDEX('D. Administrativo'!F68:F87,COUNT('D. Administrativo'!C68:C87)),"")
A8: Terça-feira | B8: Gestão de Contratos | C8: 2 | D8: 7 | E8: =COUNTIF('Gestão de Contratos'!E5:L5,"S") | F8: =COUNT('Gestão de Contratos'!C25:C44) | G8: =IFERROR(MAX('Gestão de Contratos'!F25:F44),"") | H8: =IFERROR(INDEX('Gestão de Contratos'!F25:F44,COUNT('Gestão de Contratos'!C25:C44)),"")
A9: Quarta-feira | B9: Direito Constitucional | C9: 9 | D9: 12 | E9: =COUNTIF('D. Constitucional'!E5:L5,"S") | F9: =COUNT('D. Constitucional'!C40:C59) | G9: =IFERROR(MAX('D. Constitucional'!F40:F59),"") | H9: =IFERROR(INDEX('D. Constitucional'!F40:F59,COUNT('D. Constitucional'!C40:C59)),"")
A10: Quarta-feira | B10: Lei Orgânica do TCDF e Regimento Interno | C10: 2 | D10: 10 | E10: =COUNTIF('LO e RI do TCDF'!E5:L5,"S") | F10: =COUNT('LO e RI do TCDF'!C24:C43) | G10: =IFERROR(MAX('LO e RI do TCDF'!F24:F43),"") | H10: =IFERROR(INDEX('LO e RI do TCDF'!F24:F43,COUNT('LO e RI do TCDF'!C24:C43)),"")
A11: Quarta-feira | B11: Lei Orgânica do Distrito Federal | C11: 5 | D11: 6 | E11: =COUNTIF('LODF'!E5:L5,"S") | F11: =COUNT('LODF'!C18:C37) | G11: =IFERROR(MAX('LODF'!F18:F37),"") | H11: =IFERROR(INDEX('LODF'!F18:F37,COUNT('LODF'!C18:C37)),"")
A12: Quinta-feira | B12: Administração Geral e Pública | C12: 9 | D12: 15 | E12: =COUNTIF('Adm. Geral e Pública'!E5:L5,"S") | F12: =COUNT('Adm. Geral e Pública'!C48:C67) | G12: =IFERROR(MAX('Adm. Geral e Pública'!F48:F67),"") | H12: =IFERROR(INDEX('Adm. Geral e Pública'!F48:F67,COUNT('Adm. Geral e Pública'!C48:C67)),"")
A13: Quinta-feira | B13: Análise de Dados, Noções de Estatística e Inteligência Artificial | C13: 5 | D13: 5 | E13: =COUNTIF('Análise de Dados'!E5:L5,"S") | F13: =COUNT('Análise de Dados'!C31:C50) | G13: =IFERROR(MAX('Análise de Dados'!F31:F50),"") | H13: =IFERROR(INDEX('Análise de Dados'!F31:F50,COUNT('Análise de Dados'!C31:C50)),"")
A14: Sexta-feira | B14: Regime Jurídico dos Servidores Públicos Civis do DF (LC 840/2011) | C14: 1 | D14: 8 | E14: =COUNTIF('LC 840 Servidores'!E5:L5,"S") | F14: =COUNT('LC 840 Servidores'!C21:C40) | G14: =IFERROR(MAX('LC 840 Servidores'!F21:F40),"") | H14: =IFERROR(INDEX('LC 840 Servidores'!F21:F40,COUNT('LC 840 Servidores'!C21:C40)),"")
A15: Sexta-feira | B15: Direito Previdenciário | C15: 5 | D15: 8 | E15: =COUNTIF('D. Previdenciário'!E5:L5,"S") | F15: =COUNT('D. Previdenciário'!C20:C39) | G15: =IFERROR(MAX('D. Previdenciário'!F20:F39),"") | H15: =IFERROR(INDEX('D. Previdenciário'!F20:F39,COUNT('D. Previdenciário'!C20:C39)),"")
A16: Sexta-feira | B16: Noções de Direito Civil | C16: 6 | D16: 6 | E16: =COUNTIF('D. Civil'!E5:L5,"S") | F16: =COUNT('D. Civil'!C23:C42) | G16: =IFERROR(MAX('D. Civil'!F23:F42),"") | H16: =IFERROR(INDEX('D. Civil'!F23:F42,COUNT('D. Civil'!C23:C42)),"")
A17: Sábado | B17: Língua Portuguesa | C17: 6 | D17: 12 | E17: =COUNTIF('Português'!E5:L5,"S") | F17: =COUNT('Português'!C33:C52) | G17: =IFERROR(MAX('Português'!F33:F52),"") | H17: =IFERROR(INDEX('Português'!F33:F52,COUNT('Português'!C33:C52)),"")
A18: Sábado | B18: Raciocínio Lógico e Matemática Financeira | C18: 7 | D18: 10 | E18: =COUNTIF('RLM'!E5:L5,"S") | F18: =COUNT('RLM'!C27:C46) | G18: =IFERROR(MAX('RLM'!F27:F46),"") | H18: =IFERROR(INDEX('RLM'!F27:F46,COUNT('RLM'!C27:C46)),"")
A19: Sábado | B19: Conhecimentos do Distrito Federal e Política para Mulheres | C19: 3 | D19: 4 | E19: =COUNTIF('DF e Mulheres'!E5:L5,"S") | F19: =COUNT('DF e Mulheres'!C16:C35) | G19: =IFERROR(MAX('DF e Mulheres'!F16:F35),"") | H19: =IFERROR(INDEX('DF e Mulheres'!F16:F35,COUNT('DF e Mulheres'!C16:C35)),"")
A20: Sábado | B20: Noções de Primeiros Socorros | C20: 1 | D20: 3 | E20: =COUNTIF('Primeiros Socorros'!E5:L5,"S") | F20: =COUNT('Primeiros Socorros'!C23:C42) | G20: =IFERROR(MAX('Primeiros Socorros'!F23:F42),"") | H20: =IFERROR(INDEX('Primeiros Socorros'!F23:F42,COUNT('Primeiros Socorros'!C23:C42)),"")
B21: TOTAL | C21: =SUM(C5:C20) | D21: =SUM(D5:D20) | E21: =SUM(E5:E20) | F21: =SUM(F5:F20)
A23: COMO USAR
A24: 1. Na aba da matéria, escreva na linha 4 o nome de cada filtro que você montar no Gran (F1 a F8).
A25: 2. Marque X na coluna do filtro, na linha de cada tópico e subtópico que ele sorteia.
A26: 3. Resolveu um lote? Lance filtro, data, total, acertos e erros no bloco de baixo. As colunas % Bruto, % Líquido e Veredito são fórmulas — não digite nada nelas.
A27: 4. Filtro que bateu 90%: escreva S na linha 5 e jogue o filtro dentro do GERAL N2, o filtro único da matéria vencida, de onde saem os simulados de grupo e as revisões.
A28: 5. Tópico vencido (18/20 sobre a ementa inteira dele): marque X na coluna GERAL N2.
A30: Células amarelas são suas. O resto é fórmula ou vem do edital.
A31: Bruto = acertos ÷ total, é ele que decide o avanço. Líquido = (acertos − erros) ÷ total, é a régua da prova, onde cada erro anula um acerto. Branco conta como erro.

Sheet AFO
A1: Administração Financeira e Orçamentária | E1: Bloco P3 · Segunda-feira · 9 tópicos · 15 itens estimados do edital
A2: Escreva o nome de cada filtro na linha 4 e marque X nas linhas do que ele sorteia. Amarelo = você preenche. Aula entre parênteses = a aula cobre o tópico, mas o rótulo dela não cita esse subtópico.
D4: Nome do filtro no Gran → | M4: GERAL N2
D5: Este filtro venceu (≥90%)? →
A7: Nº | B7: Tópico e subtópico do edital | C7: Peso | D7: Aula Gran | E7: F1 | F7: F2 | G7: F3 | H7: F4 | I7: F5 | J7: F6 | K7: F7 | L7: F8 | M7: GERAL N2
A8: 1 | B8: Orçamento público | C8: 1 | D8: 1, 3, 6
B9: 1.1 conceito | D9: 1
B10: 1.2 técnicas orçamentárias | D10: 1
B11: 1.3 princípios orçamentários | D11: 6
B12: 1.4 ciclo orçamentário | D12: 3
B13: 1.5 processo orçamentário | D13: 3
A14: 2 | B14: Orçamento público no Brasil | C14: 2 | D14: 2, 4, 5, 8
B15: 2.1 sistema de planejamento e de orçamento federal | D15: 4
B16: 2.2 plano plurianual | D16: 2
B17: 2.3 diretrizes orçamentárias | D17: 2
B18: 2.4 orçamento anual | D18: 2
B19: 2.5 sistema e processo de orçamentação | D19: 4
B20: 2.6 classificações orçamentárias | D20: 8
B21: 2.7 estrutura programática | D21: 8
B22: 2.8 créditos ordinários e adicionais | D22: 5
A23: 3 | B23: Programação e execução orçamentária e financeira | C23: 2 | D23: 9
B24: 3.1 descentralização orçamentária e financeira | D24: 9
B25: 3.2 acompanhamento da execução | D25: 9
B26: 3.3 sistemas de informações | D26: 9
B27: 3.4 alterações orçamentárias | D27: 9
A28: 4 | B28: Receita pública | C28: 2 | D28: 7
B29: 4.1 conceito e classificações | D29: 7
B30: 4.2 estágios | D30: 7
B31: 4.3 fontes | D31: 7
B32: 4.4 dívida ativa | D32: 7
A33: 5 | B33: Despesa pública | C33: 2 | D33: 8, 10
B34: 5.1 conceito e classificações | D34: 8
B35: 5.2 estágios | D35: 8
B36: 5.3 restos a pagar | D36: 8
B37: 5.4 despesas de exercícios anteriores | D37: 8
B38: 5.5 dívida flutuante e fundada | D38: 8, 10
B39: 5.6 suprimento de fundos | D39: 8
A40: 6 | B40: Lei Complementar nº 101/2000 e suas alterações (Lei de Responsabilidade Fiscal) | C40: 3 | D40: 10
A41: 7 | B41: Lei nº 4.320/1964 e suas alterações | C41: 1 | D41: 8
A42: 8 | B42: Transferências voluntárias | C42: 1 | D42: 10
...

Sheet D. Tributário
A1: Noções de Direito Tributário | E1: Bloco P2 · Segunda-feira · 3 tópicos · 4 itens estimados do edital
A2: Escreva o nome de cada filtro na linha 4 e marque X nas linhas do que ele sorteia. Amarelo = você preenche. Aula entre parênteses = a aula cobre o tópico, mas o rótulo dela não cita esse subtópico.
D4: Nome do filtro no Gran → | M4: GERAL N2
D5: Este filtro venceu (≥90%)? →
A7: Nº | B7: Tópico e subtópico do edital | C7: Peso | D7: Aula Gran | E7: F1 | F7: F2 | G7: F3 | H7: F4 | I7: F5 | J7: F6 | K7: F7 | L7: F8 | M7: GERAL N2
A8: 1 | B8: Direito tributário | C8: 1 | D8: 2, 3
B9: 1.1 conceito | D9: 2
B10: 1.2 fontes do direito tributário | D10: 3
A11: 2 | B11: Sistema Tributário Nacional | C11: 2 | D11: 2, 4, 5, 7
B12: 2.1 princípios do direito tributário | D12: 2, 7
B13: 2.2 limitações constitucionais do poder de tributar da União, dos estados, do Distrito Federal e dos municípios | D13: 4, 7
B14: 2.3 repartição das receitas tributárias | D14: 5, 7
A15: 3 | B15: Tributo | C15: 1 | D15: 6, 7
B16: 3.1 conceito | D16: 6, 7
B17: 3.2 natureza jurídica | D17: 7
B18: 3.3 espécies | D18: 7
B19: 3.4 imposto | D19: 7
B20: 3.5 taxa | D20: 7
B21: 3.6 contribuição de melhoria | D21: 7
B22: 3.7 empréstimo compulsório | D22: 7
B23: 3.8 contribuições | D23: 6, 7
A26: REGISTRO DOS SIMULADOS DESTA MATÉRIA
A27: Filtro | B27: Data | C27: Total | D27: Acertos | E27: Erros | F27: % Bruto | G27: % Líquido | H27: Veredito
A28: exemplo — apague ou ignore | B28: 15/09/2026 | C28: 20 | D28: 18 | E28: 2 | F28: =IFERROR(D28/C28,"") | G28: =IFERROR((D28-E28)/C28,"") | H28: =IF(N(C28)=0,"",IF(D28/C28>=0.9,"VENCEU","REPETE"))
F29: =IFERROR(D29/C29,"") | G29: =IFERROR((D29-E29)/C29,"") | H29: =IF(N(C29)=0,"",IF(D29/C29>=0.9,"VENCEU","REPETE"))
F30: =IFERROR(D30/C30,"") | G30: =IFERROR((D30-E30)/C30,"") | H30: =IF(N(C30)=0,"",IF(D30/C30>=0.9,"VENCEU","REPETE"))
F31: =IFERROR(D31/C31,"") | G31: =IFERROR((D31-E31)/C31,"") | H31: =IF(N(C31)=0,"",IF(D31/C31>=0.9,"VENCEU","REPETE"))
F32: =IFERROR(D32/C32,"") | G32: =IFERROR((D32-E32)/C32,"") | H32: =IF(N(C32)=0,"",IF(D32/C32>=0.9,"VENCEU","REPETE"))
F33: =IFERROR(D33/C33,"") | G33: =IFERROR((D33-E33)/C33,"") | H33: =IF(N(C33)=0,"",IF(D33/C33>=0.9,"VENCEU","REPETE"))
F34: =IFERROR(D34/C34,"") | G34: =IFERROR((D34-E34)/C34,"") | H34: =IF(N(C34)=0,"",IF(D34/C34>=0.9,"VENCEU","REPETE"))
F35: =IFERROR(D35/C35,"") | G35: =IFERROR((D35-E35)/C35,"") | H35: =IF(N(C35)=0,"",IF(D35/C35>=0.9,"VENCEU","REPETE"))
F36: =IFERROR(D36/C36,"") | G36: =IFERROR((D36-E36)/C36,"") | H36: =IF(N(C36)=0,"",IF(D36/C36>=0.9,"VENCEU","REPETE"))
F37: =IFERROR(D37/C37,"") | G37: =IFERROR((D37-E37)/C37,"") | H37: =IF(N(C37)=0,"",IF(D37/C37>=0.9,"VENCEU","REPETE"))
F38: =IFERROR(D38/C38,"") | G38: =IFERROR((D38-E38)/C38,"") | H38: =IF(N(C38)=0,"",IF(D38/C38>=0.9,"VENCEU","REPETE"))
F39: =IFERROR(D39/C39,"") | G39: =IFERROR((D39-E39)/C39,"") | H39: =IF(N(C39)=0,"",IF(D39/C39>=0.9,"VENCEU","REPETE"))
F40: =IFERROR(D40/C40,"") | G40: =IFERROR((D40-E40)/C40,"") | H40: =IF(N(C40)=0,"",IF(D40/C40>=0.9,"VENCEU","REPETE"))
... F48: =IFERROR(D48/C48,"") | G48: =IFERROR((D48-E48)/C48,"") | H48: =IF(N(C48)=0,"",IF(D48/C48>=0.9,"VENCEU","REPETE"))

Sheet D. Administrativo
A1: Direito Administrativo | E1: Bloco P3 · Terça-feira · 14 tópicos · 25 itens estimados do edital
A2: Escreva o nome de cada filtro na linha 4 e marque X nas linhas do que ele sorteia. Amarelo = você preenche. Aula entre parênteses = a aula cobre o tópico, mas o rótulo dela não cita esse subtópico.
D4: Nome do filtro no Gran → | M4: GERAL N2
D5: Este filtro venceu (≥90%)? →
A7: Nº | B7: Tópico e subtópico do edital | C7: Peso | D7: Aula Gran | E7: F1 | F7: F2 | G7: F3 | H7: F4 | I7: F5 | J7: F6 | K7: F7 | L7: F8 | M7: GERAL N2
A8: 1 | B8: Estado, governo e administração pública | C8: 1 | D8: 2
B9: 1.1 conceitos | D9: 2
B10: 1.2 elementos | D10: 2
A11: 2 | B11: Direito administrativo | C11: 1 | D11: 2
B12: 2.1 conceito | D12: 2
B13: 2.2 objeto | D13: 2
B14: 2.3 fontes | D14: 2
A15: 3 | B15: Ato administrativo | C15: 3 | D15: 5
B16: 3.1 conceito, requisitos, atributos, classificação e espécies | D16: 5
B17: 3.2 extinção do ato administrativo: cassação, anulação, revogação e convalidação | D17: 5
B18: 3.3 decadência administrativa | D18: 5
A19: 4 | B19: Agentes públicos | C19: 3 | D19: 6
B20: 4.1 disposições constitucionais aplicáveis | D20: 6
B21: 4.2 conceito | D21: 6
B22: 4.3 espécies | D22: 6
B23: 4.4 cargo, emprego e função pública (provimento, vacância, efetividade, estabilidade e vitaliciedade) | D23: 6
B24: 4.5 remuneração | D24: 6
B25: 4.6 direitos e deveres | D25: 6
B26: 4.7 responsabilidades | D26: 6
B27: 4.8 sindicância e processo administrativo disciplinar | D27: 6
A28: 5 | B28: Poderes da administração pública | C28: 2 | D28: 4
B29: 5.1 hierárquico, disciplinar, regulamentar e de polícia | D29: 4
B30: 5.2 uso e abuso do poder | D30: 4
A31: 6 | B31: Regime jurídico-administrativo | C31: 2 | D31: 2
B32: 6.1 conceito | D32: 2
B33: 6.2 princípios expressos e implícitos da administração pública | D33: 2
A34: 7 | B34: Responsabilidade civil do Estado | C34: 2 | D34: 7
B35: 7.1 evolução histórica | D35: 7
B36: 7.2 responsabilidade por ato comissivo | D36: 7
B37: 7.3 responsabilidade por omissão | D37: 7
B38: 7.4 requisitos para a demonstração da responsabilidade | D38: 7
B39: 7.5 causas excludentes e atenuantes | D39: 7
B40: 7.6 reparação do dano | D40: 7
B41: 7.7 direito de regresso | D41: 7
A42: 8 | B42: Serviços públicos | C42: 1 | D42: 8
...

Sheet Gestão de Contratos
A1: Gestão de Contratos | E1: Bloco P3 · Terça-feira · 2 tópicos · 7 itens estimados do edital
A2: Escreva o nome de cada filtro na linha 4 e marque X nas linhas do que ele sorteia. Amarelo = você preenche. Aula entre parênteses = a aula cobre o tópico, mas o rótulo dela não cita esse subtópico.
D4: Nome do filtro no Gran → | M4: GERAL N2
D5: Este filtro venceu (≥90%)? →
A7: Nº | B7: Tópico e subtópico do edital | C7: Peso | D7: Aula Gran | E7: F1 | F7: F2 | G7: F3 | H7: F4 | I7: F5 | J7: F6 | K7: F7 | L7: F8 | M7: GERAL N2
A8: 1 | B8: Legislação aplicável à contratação de bens e serviços | C8: 3 | D8: 2, 3
B9: 1.1 Lei nº 14.133/2021 | D9: 2
B10: 1.2 Instrução Normativa nº 5/2017 da Secretaria de Gestão do Ministério do Planejamento, Desenvolvimento e Gestão | D10: 3
B11: 1.3 Decreto distrital nº 44.330/2023 | D11: 2
A12: 2 | B12: Elaboração e fiscalização de contratos | C12: 4 | D12: 4
B13: 2.1 cláusulas e indicadores de nível de serviço | D13: 4
B14: 2.2 papel do fiscalizador do contrato | D14: (4)
B15: 2.3 papel do preposto da contratada | D15: (4)
B16: 2.4 acompanhamento da execução contratual | D16: (4)
B17: 2.5 registro e notificação de irregularidades | D17: (4)
B18: 2.6 definição e aplicação de penalidades e sanções administrativas | D18: (4)
B19: 2.7 equação econômico-financeira (reajuste e repactuação) | D19: 4
A22: REGISTRO DOS SIMULADOS DESTA MATÉRIA
A23: Filtro | B23: Data | C23: Total | D23: Acertos | E23: Erros | F23: % Bruto | G23: % Líquido | H23: Veredito
A24: exemplo — apague ou ignore | B24: 15/09/2026 | C24: 20 | D24: 18 | E24: 2 | F24: =IFERROR(D24/C24,"") | G24: =IFERROR((D24-E24)/C24,"") | H24: =IF(N(C24)=0,"",IF(D24/C24>=0.9,"VENCEU","REPETE"))
F25: =IFERROR(D25/C25,"") | G25: =IFERROR((D25-E25)/C25,"") | H25: =IF(N(C25)=0,"",IF(D25/C25>=0.9,"VENCEU","REPETE"))
F26: =IFERROR(D26/C26,"") | G26: =IFERROR((D26-E26)/C26,"") | H26: =IF(N(C26)=0,"",IF(D26/C26>=0.9,"VENCEU","REPETE"))
F27: =IFERROR(D27/C27,"") | G27: =IFERROR((D27-E27)/C27,"") | H27: =IF(N(C27)=0,"",IF(D27/C27>=0.9,"VENCEU","REPETE"))
F28: =IFERROR(D28/C28,"") | G28: =IFERROR((D28-E28)/C28,"") | H28: =IF(N(C28)=0,"",IF(D28/C28>=0.9,"VENCEU","REPETE"))
F29: =IFERROR(D29/C29,"") | G29: =IFERROR((D29-E29)/C29,"") | H29: =IF(N(C29)=0,"",IF(D29/C29>=0.9,"VENCEU","REPETE"))
F30: =IFERROR(D30/C30,"") | G30: =IFERROR((D30-E30)/C30,"") | H30: =IF(N(C30)=0,"",IF(D30/C30>=0.9,"VENCEU","REPETE"))
F31: =IFERROR(D31/C31,"") | G31: =IFERROR((D31-E31)/C31,"") | H31: =IF(N(C31)=0,"",IF(D31/C31>=0.9,"VENCEU","REPETE"))
F32: =IFERROR(D32/C32,"") | G32: =IFERROR((D32-E32)/C32,"") | H32: =IF(N(C32)=0,"",IF(D32/C32>=0.9,"VENCEU","REPETE"))
F33: =IFERROR(D33/C33,"") | G33: =IFERROR((D33-E33)/C33,"") | H33: =IF(N(C33)=0,"",IF(D33/C33>=0.9,"VENCEU","REPETE"))
F34: =IFERROR(D34/C34,"") | G34: =IFERROR((D34-E34)/C34,"") | H34: =IF(N(C34)=0,"",IF(D34/C34>=0.9,"VENCEU","REPETE"))
F35: =IFERROR(D35/C35,"") | G35: =IFERROR((D35-E35)/C35,"") | H35: =IF(N(C35)=0,"",IF(D35/C35>=0.9,"VENCEU","REPETE"))
F36: =IFERROR(D36/C36,"") | G36: =IFERROR((D36-E36)/C36,"") | H36: =IF(N(C36)=0,"",IF(D36/C36>=0.9,"VENCEU","REPETE"))
... F44: =IFERROR(D44/C44,"") | G44: =IFERROR((D44-E44)/C44,"") | H44: =IF(N(C44)=0,"",IF(D44/C44>=0.9,"VENCEU","REPETE"))

Sheet D. Constitucional
A1: Direito Constitucional | E1: Bloco P2 · Quarta-feira · 9 tópicos · 12 itens estimados do edital
A2: Escreva o nome de cada filtro na linha 4 e marque X nas linhas do que ele sorteia. Amarelo = você preenche. Aula entre parênteses = a aula cobre o tópico, mas o rótulo dela não cita esse subtópico.
D4: Nome do filtro no Gran → | M4: GERAL N2
D5: Este filtro venceu (≥90%)? →
A7: Nº | B7: Tópico e subtópico do edital | C7: Peso | D7: Aula Gran | E7: F1 | F7: F2 | G7: F3 | H7: F4 | I7: F5 | J7: F6 | K7: F7 | L7: F8 | M7: GERAL N2
A8: 1 | B8: Constituição da República Federativa do Brasil de 1988 | C8: 1 | D8: 2
B9: 1.1 princípios fundamentais | D9: 2
A10: 2 | B10: Aplicabilidade das normas constitucionais | C10: 1 | D10: 4
B11: 2.1 normas de eficácia plena, contida e limitada; normas programáticas | D11: 4
B12: 2.2 emenda, reforma e revisão constitucional | D12: 4
A13: 3 | B13: Direitos e garantias fundamentais | C13: 2 | D13: 3
B14: 3.1 direitos e deveres individuais e coletivos, direitos sociais, direitos de nacionalidade, direitos políticos, partidos políticos | D14: 3
A15: 4 | B15: Organização político-administrativa do Estado | C15: 1 | D15: 5
B16: 4.1 Estado federal brasileiro, União, estados, Distrito Federal e municípios | D16: 5
A17: 5 | B17: Administração pública | C17: 2 | D17: 6
B18: 5.1 disposições gerais | D18: (6)
B19: 5.2 servidores públicos | D19: 6
A20: 6 | B20: Poder Executivo | C20: 1 | D20: 7
B21: 6.1 atribuições e responsabilidades do presidente da República | D21: 7
A22: 7 | B22: Poder Legislativo | C22: 2 | D22: 8
B23: 7.1 estrutura | D23: (8)
B24: 7.2 funcionamento e atribuições | D24: (8)
B25: 7.3 processo legislativo | D25: (8)
B26: 7.4 fiscalização contábil, financeira e orçamentária | D26: 8
B27: 7.5 comissões parlamentares de inquérito | D27: (8)
A28: 8 | B28: Poder Judiciário | C28: 1 | D28: 9
B29: 8.1 disposições gerais | D29: 9
B30: 8.2 órgãos do Poder Judiciário | D30: 9
A31: 9 | B31: Funções essenciais à justiça | C31: 1 | D31: 10
B32: 9.1 Ministério Público | D32: 10
B33: 9.2 advocacia pública | D33: 10
B34: 9.3 Defensoria Pública | D34: 10
A37: REGISTRO DOS SIMULADOS DESTA MATÉRIA
A38: Filtro | B38: Data | C38: Total | D38: Acertos | E38: Erros | F38: % Bruto | G38: % Líquido | H38: Veredito
A39: exemplo — apague ou ignore | B39: 15/09/2026 | C39: 20 | D39: 18 | E39: 2 | F39: =IFERROR(D39/C39,"") | G39: =IFERROR((D39-E39)/C39,"") | H39: =IF(N(C39)=0,"",IF(D39/C39>=0.9,"VENCEU","REPETE"))
F40: =IFERROR(D40/C40,"") | G40: =IFERROR((D40-E40)/C40,"") | H40: =IF(N(C40)=0,"",IF(D40/C40>=0.9,"VENCEU","REPETE"))
F41: =IFERROR(D41/C41,"") | G41: =IFERROR((D41-E41)/C41,"") | H41: =IF(N(C41)=0,"",IF(D41/C41>=0.9,"VENCEU","REPETE"))
F42: =IFERROR(D42/C42,"") | G42: =IFERROR((D42-E42)/C42,"") | H42: =IF(N(C42)=0,"",IF(D42/C42>=0.9,"VENCEU","REPETE"))
F43: =IFERROR(D43/C43,"") | G43: =IFERROR((D43-E43)/C43,"") | H43: =IF(N(C43)=0,"",IF(D43/C43>=0.9,"VENCEU","REPETE"))
F44: =IFERROR(D44/C44,"") | G44: =IFERROR((D44-E44)/C44,"") | H44: =IF(N(C44)=0,"",IF(D44/C44>=0.9,"VENCEU","REPETE"))
...

Sheet LO e RI do TCDF
A1: Lei Orgânica do TCDF e Regimento Interno | E1: Bloco P2 · Quarta-feira · 2 tópicos · 10 itens estimados do edital
A2: Escreva o nome de cada filtro na linha 4 e marque X nas linhas do que ele sorteia. Amarelo = você preenche. Aula entre parênteses = a aula cobre o tópico, mas o rótulo dela não cita esse subtópico.
D4: Nome do filtro no Gran → | M4: GERAL N2
D5: Este filtro venceu (≥90%)? →
A7: Nº | B7: Tópico e subtópico do edital | C7: Peso | D7: Aula Gran | E7: F1 | F7: F2 | G7: F3 | H7: F4 | I7: F5 | J7: F6 | K7: F7 | L7: F8 | M7: GERAL N2
A8: 1 | B8: Lei Orgânica do TCDF | C8: 5 | D8: 2
B9: 1.1 natureza, competência e jurisdição | D9: 2
B10: 1.2 composição | D10: (2)
B11: 1.3 Plenário e câmaras | D11: (2)
B12: 1.4 presidente, vice-presidente, conselheiros, auditores e Ministério Público | D12: (2)
B13: 1.5 serviços auxiliares do TCDF | D13: 2
A14: 2 | B14: Regimento Interno do TCDF | C14: 5 | D14: 3
B15: 2.1 Resolução nº 296/2016, títulos I, II e III (art. 1º a 116) | D15: 3
B16: Título I — Da organização e do funcionamento do Tribunal (subdivisão sugerida)
B17: Título II — Da competência e da jurisdição (subdivisão sugerida)
B18: Título III — Dos processos: instauração, instrução, julgamento e recursos (até o art. 116) (subdivisão sugerida)
A21: REGISTRO DOS SIMULADOS DESTA MATÉRIA
A22: Filtro | B22: Data | C22: Total | D22: Acertos | E22: Erros | F22: % Bruto | G22: % Líquido | H22: Veredito
A23: exemplo — apague ou ignore | B23: 15/09/2026 | C23: 20 | D23: 18 | E23: 2 | F23: =IFERROR(D23/C23,"") | G23: =IFERROR((D23-E23)/C23,"") | H23: =IF(N(C23)=0,"",IF(D23/C23>=0.9,"VENCEU","REPETE"))
F24: =IFERROR(D24/C24,"") | G24: =IFERROR((D24-E24)/C24,"") | H24: =IF(N(C24)=0,"",IF(D24/C24>=0.9,"VENCEU","REPETE"))
F25: =IFERROR(D25/C25,"") | G25: =IFERROR((D25-E25)/C25,"") | H25: =IF(N(C25)=0,"",IF(D25/C25>=0.9,"VENCEU","REPETE"))
F26: =IFERROR(D26/C26,"") | G26: =IFERROR((D26-E26)/C26,"") | H26: =IF(N(C26)=0,"",IF(D26/C26>=0.9,"VENCEU","REPETE"))
F27: =IFERROR(D27/C27,"") | G27: =IFERROR((D27-E27)/C27,"") | H27: =IF(N(C27)=0,"",IF(D27/C27>=0.9,"VENCEU","REPETE"))
F28: =IFERROR(D28/C28,"") | G28: =IFERROR((D28-E28)/C28,"") | H28: =IF(N(C28)=0,"",IF(D28/C28>=0.9,"VENCEU","REPETE"))
F29: =IFERROR(D29/C29,"") | G29: =IFERROR((D29-E29)/C29,"") | H29: =IF(N(C29)=0,"",IF(D29/C29>=0.9,"VENCEU","REPETE"))
F30: =IFERROR(D30/C30,"") | G30: =IFERROR((D30-E30)/C30,"") | H30: =IF(N(C30)=0,"",IF(D30/C30>=0.9,"VENCEU","REPETE"))
F31: =IFERROR(D31/C31,"") | G31: =IFERROR((D31-E31)/C31,"") | H31: =IF(N(C31)=0,"",IF(D31/C31>=0.9,"VENCEU","REPETE"))
F32: =IFERROR(D32/C32,"") | G32: =IFERROR((D32-E32)/C32,"") | H32: =IF(N(C32)=0,"",IF(D32/C32>=0.9,"VENCEU","REPETE"))
F33: =IFERROR(D33/C33,"") | G33: =IFERROR((D33-E33)/C33,"") | H33: =IF(N(C33)=0,"",IF(D33/C33>=0.9,"VENCEU","REPETE"))
F34: =IFERROR(D34/C34,"") | G34: =IFERROR((D34-E34)/C34,"") | H34: =IF(N(C34)=0,"",IF(D34/C34>=0.9,"VENCEU","REPETE"))
F35: =IFERROR(D35/C35,"") | G35: =IFERROR((D35-E35)/C35,"") | H35: =IF(N(C35)=0,"",IF(D35/C35>=0.9,"VENCEU","REPETE"))
... F43: =IFERROR(D43/C43,"") | G43: =IFERROR((D43-E43)/C43,"") | H43: =IF(N(C43)=0,"",IF(D43/C43>=0.9,"VENCEU","REPETE"))

Sheet LODF
A1: Lei Orgânica do Distrito Federal | E1: Bloco P1 · Quarta-feira · 5 tópicos · 6 itens estimados do edital
A2: Escreva o nome de cada filtro na linha 4 e marque X nas linhas do que ele sorteia. Amarelo = você preenche. Aula entre parênteses = a aula cobre o tópico, mas o rótulo dela não cita esse subtópico.
D4: Nome do filtro no Gran → | M4: GERAL N2
D5: Este filtro venceu (≥90%)? →
A7: Nº | B7: Tópico e subtópico do edital | C7: Peso | D7: Aula Gran | E7: F1 | F7: F2 | G7: F3 | H7: F4 | I7: F5 | J7: F6 | K7: F7 | L7: F8 | M7: GERAL N2
A8: 1 | B8: Fundamentos da organização dos poderes e do Distrito Federal | C8: 1 | D8: 2
A9: 2 | B9: Organização do Distrito Federal | C9: 1 | D9: 2
A10: 3 | B10: Organização dos poderes | C10: 2 | D10: 2
A11: 4 | B11: Tributação e orçamento do Distrito Federal | C11: 1 | D11: 2
A12: 5 | B12: Ordem econômica do Distrito Federal | C12: 1 | D12: 2
A15: REGISTRO DOS SIMULADOS DESTA MATÉRIA
A16: Filtro | B16: Data | C16: Total | D16: Acertos | E16: Erros | F16: % Bruto | G16: % Líquido | H16: Veredito
A17: exemplo — apague ou ignore | B17: 15/09/2026 | C17: 20 | D17: 18 | E17: 2 | F17: =IFERROR(D17/C17,"") | G17: =IFERROR((D17-E17)/C17,"") | H17: =IF(N(C17)=0,"",IF(D17/C17>=0.9,"VENCEU","REPETE"))
F18: =IFERROR(D18/C18,"") | G18: =IFERROR((D18-E18)/C18,"") | H18: =IF(N(C18)=0,"",IF(D18/C18>=0.9,"VENCEU","REPETE"))
F19: =IFERROR(D19/C19,"") | G19: =IFERROR((D19-E19)/C19,"") | H19: =IF(N(C19)=0,"",IF(D19/C19>=0.9,"VENCEU","REPETE"))
F20: =IFERROR(D20/C20,"") | G20: =IFERROR((D20-E20)/C20,"") | H20: =IF(N(C20)=0,"",IF(D20/C20>=0.9,"VENCEU","REPETE"))
F21: =IFERROR(D21/C21,"") | G21: =IFERROR((D21-E21)/C21,"") | H21: =IF(N(C21)=0,"",IF(D21/C21>=0.9,"VENCEU","REPETE"))
F22: =IFERROR(D22/C22,"") | G22: =IFERROR((D22-E22)/C22,"") | H22: =IF(N(C22)=0,"",IF(D22/C22>=0.9,"VENCEU","REPETE"))
F23: =IFERROR(D23/C23,"") | G23: =IFERROR((D23-E23)/C23,"") | H23: =IF(N(C23)=0,"",IF(D23/C23>=0.9,"VENCEU","REPETE"))
F24: =IFERROR(D24/C24,"") | G24: =IFERROR((D24-E24)/C24,"") | H24: =IF(N(C24)=0,"",IF(D24/C24>=0.9,"VENCEU","REPETE"))
F25: =IFERROR(D25/C25,"") | G25: =IFERROR((D25-E25)/C25,"") | H25: =IF(N(C25)=0,"",IF(D25/C25>=0.9,"VENCEU","REPETE"))
F26: =IFERROR(D26/C26,"") | G26: =IFERROR((D26-E26)/C26,"") | H26: =IF(N(C26)=0,"",IF(D26/C26>=0.9,"VENCEU","REPETE"))
F27: =IFERROR(D27/C27,"") | G27: =IFERROR((D27-E27)/C27,"") | H27: =IF(N(C27)=0,"",IF(D27/C27>=0.9,"VENCEU","REPETE"))
F28: =IFERROR(D28/C28,"") | G28: =IFERROR((D28-E28)/C28,"") | H28: =IF(N(C28)=0,"",IF(D28/C28>=0.9,"VENCEU","REPETE"))
F29: =IFERROR(D29/C29,"") | G29: =IFERROR((D29-E29)/C29,"") | H29: =IF(N(C29)=0,"",IF(D29/C29>=0.9,"VENCEU","REPETE"))
... F37: =IFERROR(D37/C37,"") | G37: =IFERROR((D37-E37)/C37,"") | H37: =IF(N(C37)=0,"",IF(D37/C37>=0.9,"VENCEU","REPETE"))

Sheet Adm. Geral e Pública
A1: Administração Geral e Pública | E1: Bloco P3 · Quinta-feira · 9 tópicos · 15 itens estimados do edital
A2: Escreva o nome de cada filtro na linha 4 e marque X nas linhas do que ele sorteia. Amarelo = você preenche. Aula entre parênteses = a aula cobre o tópico, mas o rótulo dela não cita esse subtópico.
D4: Nome do filtro no Gran → | M4: GERAL N2
D5: Este filtro venceu (≥90%)? →
A7: Nº | B7: Tópico e subtópico do edital | C7: Peso | D7: Aula Gran | E7: F1 | F7: F2 | G7: F3 | H7: F4 | I7: F5 | J7: F6 | K7: F7 | L7: F8 | M7: GERAL N2
A8: 1 | B8: Evolução da administração | C8: 2 | D8: 2
B9: 1.1 perspectiva clássica (administração científica, organizações burocráticas) | D9: 2
B10: 1.2 perspectiva humanista (movimento das relações humanas, perspectiva dos recursos humanos, abordagem das ciências comportamentais) | D10: 2
B11: 1.3 ciência administrativa (pensamento sistêmico, teoria da contingência) | D11: 2
A12: 2 | B12: Evolução da administração do setor público brasileiro | C12: 1 | D12: 5
B13: 2.1 estrutura organizacional do Estado: três poderes | D13: 5
B14: 2.2 formas de administração pública | D14: 5
A15: 3 | B15: Administração pública patrimonialista | C15: 2 | D15: 5
B16: 3.1 administração pública burocrática | D16: 5
B17: 3.2 administração pública gerencial | D17: 5
A18: 4 | B18: Governança | C18: 3 | D18: 6
B19: 4.1 princípios da governança pública (capacidade de resposta, integridade, confiabilidade, melhoria regulatória, transparência, prestação de contas e responsabilidades) | D19: 6
B20: 4.2 práticas e mecanismos de governança pública (liderança, estratégia, controle) | D20: 6
A21: 5 | B21: Funções administrativas: planejamento, organização, direção e controle | C21: 1 | D21: 2
A22: 6 | B22: Ferramentas da administração | C22: 2 | D22: 3
B23: 6.1 análise SWOT | D23: 3
B24: 6.2 matriz GUT | D24: 3
B25: 6.3 5W2H | D25: 3
B26: 6.4 ciclo PDCA | D26: 3
B27: 6.5 mapas estratégicos | D27: 3
B28: 6.6 benchmarking | D28: 3
B29: 6.7 fatores críticos de sucesso | D29: 3
A30: 7 | B30: Modelagem de processos | C30: 2 | D30: 3
B31: 7.1 propósito da modelagem de processos | D31: 3
B32: 7.2 notações: BPMN, cadeia de processos orientada a eventos (EPC), IDEF0, cadeia de valor | D32: 3
A33: 8 | B33: Gestão de pessoas por competências | C33: 1 | D33: 4
B34: 8.1 conhecimentos, habilidades e atitudes (CHA) | D34: 4
B35: 8.2 matriz de competência | D35: 4
B36: 8.3 avaliação participativa por objetivo (APPO) | D36: 4
B37: 8.4 liderança | D37: 4
B38: 8.5 motivação | D38: 4
A39: 9 | B39: Gestão de projetos e portfólios | C39: 1 | D39: 7, 8, 9
B40: 9.1 padrões de referência em gerenciamento de projetos (PMBOK, Prince, Scrum e métodos ágeis) | D40: 7, 8, 9
B41: 9.2 cronogramas (decomposição de escopo, sequenciamento de atividades, estimativa de esforço e duração, alocação de pessoas) | D41: 7
B42: 9.3 Kanban | D42: 9
...

Sheet Análise de Dados
A1: Análise de Dados, Noções de Estatística e Inteligência Artificial | E1: Bloco P2 · Quinta-feira · 5 tópicos · 5 itens estimados do edital
A2: Escreva o nome de cada filtro na linha 4 e marque X nas linhas do que ele sorteia. Amarelo = você preenche. Aula entre parênteses = a aula cobre o tópico, mas o rótulo dela não cita esse subtópico.
D4: Nome do filtro no Gran → | M4: GERAL N2
D5: Este filtro venceu (≥90%)? →
A7: Nº | B7: Tópico e subtópico do edital | C7: Peso | D7: Aula Gran | E7: F1 | F7: F2 | G7: F3 | H7: F4 | I7: F5 | J7: F6 | K7: F7 | L7: F8 | M7: GERAL N2
A8: 1 | B8: Fundamentos de análise de dados | C8: 1 | D8: 2
B9: 1.1 tipos de dados (estruturados e não estruturados; quantitativos e qualitativos) | D9: 2
B10: 1.2 produtos da análise de dados (base de dados, relatórios, planilhas e dashboards) | D10: 2
A11: 2 | B11: Estatística descritiva e análise exploratória de dados | C11: 1 | D11: 3
B12: 2.1 tabelas de distribuição de frequências, medidas de tendência central (média, mediana e moda) e medidas de dispersão (variância e desvio-padrão) voltadas à identificação de anomalias | D12: 3
B13: 2.2 identificação de outliers e análise de séries históricas | D13: 3
A14: 3 | B14: Introdução à visualização de dados e storytelling | C14: 1 | D14: 4, 5
B15: 3.1 tipos de gráficos (barras, pizza, linha, dispersão, histograma) | D15: 4
B16: 3.2 boas práticas para construção de gráficos | D16: 4
B17: 3.3 princípios de narrativa com dados | D17: 5
A18: 4 | B18: Inteligência artificial generativa | C18: 1 | D18: 6
B19: 4.1 engenharia de prompt (contexto, persona, exemplos e estrutura de saída; encadeamento de prompt) | D19: 6
B20: 4.2 vieses cognitivos | D20: 6
B21: 4.3 ética no uso de dados e inteligência artificial | D21: 6
A22: 5 | B22: Utilização de Excel (Microsoft 365) para análise de dados | C22: 1 | D22: 7, 8, 9
B23: 5.1 operação em Microsoft Excel avançado (Power Query para extração e tratamento de dados) | D23: 8
B24: 5.2 fórmulas lógicas, financeiras e de busca | D24: 7
B25: 5.3 tabelas dinâmicas e tratamento de grandes bases relacionais | D25: 9
A28: REGISTRO DOS SIMULADOS DESTA MATÉRIA
A29: Filtro | B29: Data | C29: Total | D29: Acertos | E29: Erros | F29: % Bruto | G29: % Líquido | H29: Veredito
A30: exemplo — apague ou ignore | B30: 15/09/2026 | C30: 20 | D30: 18 | E30: 2 | F30: =IFERROR(D30/C30,"") | G30: =IFERROR((D30-E30)/C30,"") | H30: =IF(N(C30)=0,"",IF(D30/C30>=0.9,"VENCEU","REPETE"))
F31: =IFERROR(D31/C31,"") | G31: =IFERROR((D31-E31)/C31,"") | H31: =IF(N(C31)=0,"",IF(D31/C31>=0.9,"VENCEU","REPETE"))
F32: =IFERROR(D32/C32,"") | G32: =IFERROR((D32-E32)/C32,"") | H32: =IF(N(C32)=0,"",IF(D32/C32>=0.9,"VENCEU","REPETE"))
F33: =IFERROR(D33/C33,"") | G33: =IFERROR((D33-E33)/C33,"") | H33: =IF(N(C33)=0,"",IF(D33/C33>=0.9,"VENCEU","REPETE"))
F34: =IFERROR(D34/C34,"") | G34: =IFERROR((D34-E34)/C34,"") | H34: =IF(N(C34)=0,"",IF(D34/C34>=0.9,"VENCEU","REPETE"))
F35: =IFERROR(D35/C35,"") | G35: =IFERROR((D35-E35)/C35,"") | H35: =IF(N(C35)=0,"",IF(D35/C35>=0.9,"VENCEU","REPETE"))
F36: =IFERROR(D36/C36,"") | G36: =IFERROR((D36-E36)/C36,"") | H36: =IF(N(C36)=0,"",IF(D36/C36>=0.9,"VENCEU","REPETE"))
F37: =IFERROR(D37/C37,"") | G37: =IFERROR((D37-E37)/C37,"") | H37: =IF(N(C37)=0,"",IF(D37/C37>=0.9,"VENCEU","REPETE"))
F38: =IFERROR(D38/C38,"") | G38: =IFERROR((D38-E38)/C38,"") | H38: =IF(N(C38)=0,"",IF(D38/C38>=0.9,"VENCEU","REPETE"))
F39: =IFERROR(D39/C39,"") | G39: =IFERROR((D39-E39)/C39,"") | H39: =IF(N(C39)=0,"",IF(D39/C39>=0.9,"VENCEU","REPETE"))
F40: =IFERROR(D40/C40,"") | G40: =IFERROR((D40-E40)/C40,"") | H40: =IF(N(C40)=0,"",IF(D40/C40>=0.9,"VENCEU","REPETE"))
F41: =IFERROR(D41/C41,"") | G41: =IFERROR((D41-E41)/C41,"") | H41: =IF(N(C41)=0,"",IF(D41/C41>=0.9,"VENCEU","REPETE"))
F42: =IFERROR(D42/C42,"") | G42: =IFERROR((D42-E42)/C42,"") | H42: =IF(N(C42)=0,"",IF(D42/C42>=0.9,"VENCEU","REPETE"))
... F50: =IFERROR(D50/C50,"") | G50: =IFERROR((D50-E50)/C50,"") | H50: =IF(N(C50)=0,"",IF(D50/C50>=0.9,"VENCEU","REPETE"))

Sheet LC 840 Servidores
A1: Regime Jurídico dos Servidores Públicos Civis do DF (LC 840/2011) | E1: Bloco P3 · Sexta-feira · 1 tópicos · 8 itens estimados do edital
A2: Escreva o nome de cada filtro na linha 4 e marque X nas linhas do que ele sorteia. Amarelo = você preenche. Aula entre parênteses = a aula cobre o tópico, mas o rótulo dela não cita esse subtópico.
D4: Nome do filtro no Gran → | M4: GERAL N2
D5: Este filtro venceu (≥90%)? →
A7: Nº | B7: Tópico e subtópico do edital | C7: Peso | D7: Aula Gran | E7: F1 | F7: F2 | G7: F3 | H7: F4 | I7: F5 | J7: F6 | K7: F7 | L7: F8 | M7: GERAL N2
A8: 1 | B8: Lei Complementar nº 840/2011 (regime jurídico dos servidores públicos civis do Distrito Federal, das autarquias e das fundações públicas distritais) | C8: 8 | D8: 2
B9: Disposições preliminares, cargo público e provimento (nomeação, posse, exercício, estágio probatório) (subdivisão sugerida)
B10: Vacância, remoção, redistribuição e substituição (subdivisão sugerida)
B11: Direitos e vantagens: remuneração, vencimento, vantagens, indenizações e gratificações (subdivisão sugerida)
B12: Férias, licenças, afastamentos e concessões (subdivisão sugerida)
B13: Deveres, proibições, acumulação e responsabilidades do servidor (subdivisão sugerida)
B14: Regime disciplinar: penalidades, sindicância, processo administrativo disciplinar e prescrição (subdivisão sugerida)
B15: Seguridade do servidor e disposições finais (subdivisão sugerida)
A18: REGISTRO DOS SIMULADOS DESTA MATÉRIA
A19: Filtro | B19: Data | C19: Total | D19: Acertos | E19: Erros | F19: % Bruto | G19: % Líquido | H19: Veredito
A20: exemplo — apague ou ignore | B20: 15/09/2026 | C20: 20 | D20: 18 | E20: 2 | F20: =IFERROR(D20/C20,"") | G20: =IFERROR((D20-E20)/C20,"") | H20: =IF(N(C20)=0,"",IF(D20/C20>=0.9,"VENCEU","REPETE"))
F21: =IFERROR(D21/C21,"") | G21: =IFERROR((D21-E21)/C21,"") | H21: =IF(N(C21)=0,"",IF(D21/C21>=0.9,"VENCEU","REPETE"))
F22: =IFERROR(D22/C22,"") | G22: =IFERROR((D22-E22)/C22,"") | H22: =IF(N(C22)=0,"",IF(D22/C22>=0.9,"VENCEU","REPETE"))
F23: =IFERROR(D23/C23,"") | G23: =IFERROR((D23-E23)/C23,"") | H23: =IF(N(C23)=0,"",IF(D23/C23>=0.9,"VENCEU","REPETE"))
F24: =IFERROR(D24/C24,"") | G24: =IFERROR((D24-E24)/C24,"") | H24: =IF(N(C24)=0,"",IF(D24/C24>=0.9,"VENCEU","REPETE"))
F25: =IFERROR(D25/C25,"") | G25: =IFERROR((D25-E25)/C25,"") | H25: =IF(N(C25)=0,"",IF(D25/C25>=0.9,"VENCEU","REPETE"))
F26: =IFERROR(D26/C26,"") | G26: =IFERROR((D26-E26)/C26,"") | H26: =IF(N(C26)=0,"",IF(D26/C26>=0.9,"VENCEU","REPETE"))
F27: =IFERROR(D27/C27,"") | G27: =IFERROR((D27-E27)/C27,"") | H27: =IF(N(C27)=0,"",IF(D27/C27>=0.9,"VENCEU","REPETE"))
F28: =IFERROR(D28/C28,"") | G28: =IFERROR((D28-E28)/C28,"") | H28: =IF(N(C28)=0,"",IF(D28/C28>=0.9,"VENCEU","REPETE"))
F29: =IFERROR(D29/C29,"") | G29: =IFERROR((D29-E29)/C29,"") | H29: =IF(N(C29)=0,"",IF(D29/C29>=0.9,"VENCEU","REPETE"))
F30: =IFERROR(D30/C30,"") | G30: =IFERROR((D30-E30)/C30,"") | H30: =IF(N(C30)=0,"",IF(D30/C30>=0.9,"VENCEU","REPETE"))
F31: =IFERROR(D31/C31,"") | G31: =IFERROR((D31-E31)/C31,"") | H31: =IF(N(C31)=0,"",IF(D31/C31>=0.9,"VENCEU","REPETE"))
F32: =IFERROR(D32/C32,"") | G32: =IFERROR((D32-E32)/C32,"") | H32: =IF(N(C32)=0,"",IF(D32/C32>=0.9,"VENCEU","REPETE"))
... F40: =IFERROR(D40/C40,"") | G40: =IFERROR((D40-E40)/C40,"") | H40: =IF(N(C40)=0,"",IF(D40/C40>=0.9,"VENCEU","REPETE"))

Sheet D. Previdenciário
A1: Direito Previdenciário | E1: Bloco P2 · Sexta-feira · 5 tópicos · 8 itens estimados do edital
A2: Escreva o nome de cada filtro na linha 4 e marque X nas linhas do que ele sorteia. Amarelo = você preenche. Aula entre parênteses = a aula cobre o tópico, mas o rótulo dela não cita esse subtópico.
D4: Nome do filtro no Gran → | M4: GERAL N2
D5: Este filtro venceu (≥90%)? →
A7: Nº | B7: Tópico e subtópico do edital | C7: Peso | D7: Aula Gran | E7: F1 | F7: F2 | G7: F3 | H7: F4 | I7: F5 | J7: F6 | K7: F7 | L7: F8 | M7: GERAL N2
A8: 1 | B8: Seguridade social | C8: 1 | D8: 2, 3
B9: 1.1 origem e evolução legislativa no Brasil | D9: 2
B10: 1.2 conceito, organização e princípios constitucionais | D10: 3
A11: 2 | B11: Regime geral da previdência social – RGPS: Lei federal nº 8.212/1991 e Lei federal nº 8.213/1991 | C11: 2 | D11: 4, 5
A12: 3 | B12: Regime próprio de previdência social dos servidores públicos – RPPS | C12: 2 | D12: 6
A13: 4 | B13: Regime Próprio de Previdência Social do Distrito Federal – RPPS/DF: Lei Complementar distrital nº 769/2008 | C13: 2 | D13: 7
A14: 5 | B14: Previdência complementar: Lei Complementar federal nº 108/2001, Lei Complementar federal nº 109/2001 e Lei Complementar distrital nº 932/2017 | C14: 1 | D14: 8, 9
A17: REGISTRO DOS SIMULADOS DESTA MATÉRIA
A18: Filtro | B18: Data | C18: Total | D18: Acertos | E18: Erros | F18: % Bruto | G18: % Líquido | H18: Veredito
A19: exemplo — apague ou ignore | B19: 15/09/2026 | C19: 20 | D19: 18 | E19: 2 | F19: =IFERROR(D19/C19,"") | G19: =IFERROR((D19-E19)/C19,"") | H19: =IF(N(C19)=0,"",IF(D19/C19>=0.9,"VENCEU","REPETE"))
F20: =IFERROR(D20/C20,"") | G20: =IFERROR((D20-E20)/C20,"") | H20: =IF(N(C20)=0,"",IF(D20/C20>=0.9,"VENCEU","REPETE"))
F21: =IFERROR(D21/C21,"") | G21: =IFERROR((D21-E21)/C21,"") | H21: =IF(N(C21)=0,"",IF(D21/C21>=0.9,"VENCEU","REPETE"))
F22: =IFERROR(D22/C22,"") | G22: =IFERROR((D22-E22)/C22,"") | H22: =IF(N(C22)=0,"",IF(D22/C22>=0.9,"VENCEU","REPETE"))
F23: =IFERROR(D23/C23,"") | G23: =IFERROR((D23-E23)/C23,"") | H23: =IF(N(C23)=0,"",IF(D23/C23>=0.9,"VENCEU","REPETE"))
F24: =IFERROR(D24/C24,"") | G24: =IFERROR((D24-E24)/C24,"") | H24: =IF(N(C24)=0,"",IF(D24/C24>=0.9,"VENCEU","REPETE"))
F25: =IFERROR(D25/C25,"") | G25: =IFERROR((D25-E25)/C25,"") | H25: =IF(N(C25)=0,"",IF(D25/C25>=0.9,"VENCEU","REPETE"))
F26: =IFERROR(D26/C26,"") | G26: =IFERROR((D26-E26)/C26,"") | H26: =IF(N(C26)=0,"",IF(D26/C26>=0.9,"VENCEU","REPETE"))
F27: =IFERROR(D27/C27,"") | G27: =IFERROR((D27-E27)/C27,"") | H27: =IF(N(C27)=0,"",IF(D27/C27>=0.9,"VENCEU","REPETE"))
F28: =IFERROR(D28/C28,"") | G28: =IFERROR((D28-E28)/C28,"") | H28: =IF(N(C28)=0,"",IF(D28/C28>=0.9,"VENCEU","REPETE"))
F29: =IFERROR(D29/C29,"") | G29: =IFERROR((D29-E29)/C29,"") | H29: =IF(N(C29)=0,"",IF(D29/C29>=0.9,"VENCEU","REPETE"))
F30: =IFERROR(D30/C30,"") | G30: =IFERROR((D30-E30)/C30,"") | H30: =IF(N(C30)=0,"",IF(D30/C30>=0.9,"VENCEU","REPETE"))
F31: =IFERROR(D31/C31,"") | G31: =IFERROR((D31-E31)/C31,"") | H31: =IF(N(C31)=0,"",IF(D31/C31>=0.9,"VENCEU","REPETE"))
... F39: =IFERROR(D39/C39,"") | G39: =IFERROR((D39-E39)/C39,"") | H39: =IF(N(C39)=0,"",IF(D39/C39>=0.9,"VENCEU","REPETE"))

Sheet D. Civil
A1: Noções de Direito Civil | E1: Bloco P2 · Sexta-feira · 6 tópicos · 6 itens estimados do edital
A2: Escreva o nome de cada filtro na linha 4 e marque X nas linhas do que ele sorteia. Amarelo = você preenche. Aula entre parênteses = a aula cobre o tópico, mas o rótulo dela não cita esse subtópico.
D4: Nome do filtro no Gran → | M4: GERAL N2
D5: Este filtro venceu (≥90%)? →
A7: Nº | B7: Tópico e subtópico do edital | C7: Peso | D7: Aula Gran | E7: F1 | F7: F2 | G7: F3 | H7: F4 | I7: F5 | J7: F6 | K7: F7 | L7: F8 | M7: GERAL N2
A8: 1 | B8: Lei de Introdução às Normas do Direito Brasileiro | C8: 1 | D8: 2
A9: 2 | B9: Pessoas | C9: 1 | D9: 3
B10: 2.1 pessoas naturais | D10: 3
B11: 2.2 pessoas jurídicas | D11: 3
B12: 2.3 domicílio | D12: 3
A13: 3 | B13: Bens | C13: 1 | D13: 4
A14: 4 | B14: Fatos jurídicos | C14: 1 | D14: 5
B15: 4.1 negócio jurídico | D15: 5
A16: 5 | B16: Atos jurídicos lícitos e ilícitos | C16: 1 | D16: 5
A17: 6 | B17: Prescrição e decadência | C17: 1 | D17: 5
A20: REGISTRO DOS SIMULADOS DESTA MATÉRIA
A21: Filtro | B21: Data | C21: Total | D21: Acertos | E21: Erros | F21: % Bruto | G21: % Líquido | H21: Veredito
A22: exemplo — apague ou ignore | B22: 15/09/2026 | C22: 20 | D22: 18 | E22: 2 | F22: =IFERROR(D22/C22,"") | G22: =IFERROR((D22-E22)/C22,"") | H22: =IF(N(C22)=0,"",IF(D22/C22>=0.9,"VENCEU","REPETE"))
F23: =IFERROR(D23/C23,"") | G23: =IFERROR((D23-E23)/C23,"") | H23: =IF(N(C23)=0,"",IF(D23/C23>=0.9,"VENCEU","REPETE"))
F24: =IFERROR(D24/C24,"") | G24: =IFERROR((D24-E24)/C24,"") | H24: =IF(N(C24)=0,"",IF(D24/C24>=0.9,"VENCEU","REPETE"))
F25: =IFERROR(D25/C25,"") | G25: =IFERROR((D25-E25)/C25,"") | H25: =IF(N(C25)=0,"",IF(D25/C25>=0.9,"VENCEU","REPETE"))
F26: =IFERROR(D26/C26,"") | G26: =IFERROR((D26-E26)/C26,"") | H26: =IF(N(C26)=0,"",IF(D26/C26>=0.9,"VENCEU","REPETE"))
F27: =IFERROR(D27/C27,"") | G27: =IFERROR((D27-E27)/C27,"") | H27: =IF(N(C27)=0,"",IF(D27/C27>=0.9,"VENCEU","REPETE"))
F28: =IFERROR(D28/C28,"") | G28: =IFERROR((D28-E28)/C28,"") | H28: =IF(N(C28)=0,"",IF(D28/C28>=0.9,"VENCEU","REPETE"))
F29: =IFERROR(D29/C29,"") | G29: =IFERROR((D29-E29)/C29,"") | H29: =IF(N(C29)=0,"",IF(D29/C29>=0.9,"VENCEU","REPETE"))
F30: =IFERROR(D30/C30,"") | G30: =IFERROR((D30-E30)/C30,"") | H30: =IF(N(C30)=0,"",IF(D30/C30>=0.9,"VENCEU","REPETE"))
F31: =IFERROR(D31/C31,"") | G31: =IFERROR((D31-E31)/C31,"") | H31: =IF(N(C31)=0,"",IF(D31/C31>=0.9,"VENCEU","REPETE"))
F32: =IFERROR(D32/C32,"") | G32: =IFERROR((D32-E32)/C32,"") | H32: =IF(N(C32)=0,"",IF(D32/C32>=0.9,"VENCEU","REPETE"))
F33: =IFERROR(D33/C33,"") | G33: =IFERROR((D33-E33)/C33,"") | H33: =IF(N(C33)=0,"",IF(D33/C33>=0.9,"VENCEU","REPETE"))
F34: =IFERROR(D34/C34,"") | G34: =IFERROR((D34-E34)/C34,"") | H34: =IF(N(C34)=0,"",IF(D34/C34>=0.9,"VENCEU","REPETE"))
... F42: =IFERROR(D42/C42,"") | G42: =IFERROR((D42-E42)/C42,"") | H42: =IF(N(C42)=0,"",IF(D42/C42>=0.9,"VENCEU","REPETE"))

Sheet Português
A1: Língua Portuguesa | E1: Bloco P1 · Sábado · 6 tópicos · 12 itens estimados do edital
A2: Escreva o nome de cada filtro na linha 4 e marque X nas linhas do que ele sorteia. Amarelo = você preenche. Aula entre parênteses = a aula cobre o tópico, mas o rótulo dela não cita esse subtópico.
D4: Nome do filtro no Gran → | M4: GERAL N2
D5: Este filtro venceu (≥90%)? →
A7: Nº | B7: Tópico e subtópico do edital | C7: Peso | D7: Aula Gran | E7: F1 | F7: F2 | G7: F3 | H7: F4 | I7: F5 | J7: F6 | K7: F7 | L7: F8 | M7: GERAL N2
A8: 1 | B8: Compreensão e interpretação de textos de gêneros variados | C8: 3 | D8: 2
A9: 2 | B9: Reconhecimento de tipos e gêneros textuais | C9: 1 | D9: 4
A10: 3 | B10: Domínio da ortografia oficial | C10: 1 | D10: 16
A11: 4 | B11: Domínio dos mecanismos de coesão textual | C11: 2 | D11: 5, 7
B12: 4.1 emprego de elementos de referenciação, substituição e repetição, de conectores e de outros elementos de sequenciação textual | D12: 5
B13: 4.2 emprego de tempos e modos verbais | D13: 7
A14: 5 | B14: Domínio da estrutura morfossintática do período | C14: 3 | D14: 7, 8, 9, 10, 11, 12, 13, 14, 15
B15: 5.1 emprego das classes de palavras | D15: 7, 8
B16: 5.2 relações de coordenação entre orações e entre termos da oração | D16: 8, 10
B17: 5.3 relações de subordinação entre orações e entre termos da oração | D17: 8, 9
B18: 5.4 emprego dos sinais de pontuação | D18: 8, 11
B19: 5.5 concordância verbal e nominal | D19: 8, 14
B20: 5.6 regência verbal e nominal | D20: 8, 12
B21: 5.7 emprego do sinal indicativo de crase | D21: 8, 13
B22: 5.8 colocação dos pronomes átonos | D22: 8, 15
A23: 6 | B23: Reescrita de frases e parágrafos do texto | C23: 2 | D23: 3, 6
B24: 6.1 significação das palavras | D24: 3
B25: 6.2 substituição de palavras ou de trechos de texto | D25: 6
B26: 6.3 reorganização da estrutura de orações e de períodos do texto | D26: (3, 6)
B27: 6.4 reescrita de textos de diferentes gêneros e níveis de formalidade | D27: (3, 6)
A30: REGISTRO DOS SIMULADOS DESTA MATÉRIA
A31: Filtro | B31: Data | C31: Total | D31: Acertos | E31: Erros | F31: % Bruto | G31: % Líquido | H31: Veredito
A32: exemplo — apague ou ignore | B32: 15/09/2026 | C32: 20 | D32: 18 | E32: 2 | F32: =IFERROR(D32/C32,"") | G32: =IFERROR((D32-E32)/C32,"") | H32: =IF(N(C32)=0,"",IF(D32/C32>=0.9,"VENCEU","REPETE"))
F33: =IFERROR(D33/C33,"") | G33: =IFERROR((D33-E33)/C33,"") | H33: =IF(N(C33)=0,"",IF(D33/C33>=0.9,"VENCEU","REPETE"))
F34: =IFERROR(D34/C34,"") | G34: =IFERROR((D34-E34)/C34,"") | H34: =IF(N(C34)=0,"",IF(D34/C34>=0.9,"VENCEU","REPETE"))
F35: =IFERROR(D35/C35,"") | G35: =IFERROR((D35-E35)/C35,"") | H35: =IF(N(C35)=0,"",IF(D35/C35>=0.9,"VENCEU","REPETE"))
F36: =IFERROR(D36/C36,"") | G36: =IFERROR((D36-E36)/C36,"") | H36: =IF(N(C36)=0,"",IF(D36/C36>=0.9,"VENCEU","REPETE"))
F37: =IFERROR(D37/C37,"") | G37: =IFERROR((D37-E37)/C37,"") | H37: =IF(N(C37)=0,"",IF(D37/C37>=0.9,"VENCEU","REPETE"))
F38: =IFERROR(D38/C38,"") | G38: =IFERROR((D38-E38)/C38,"") | H38: =IF(N(C38)=0,"",IF(D38/C38>=0.9,"VENCEU","REPETE"))
F39: =IFERROR(D39/C39,"") | G39: =IFERROR((D39-E39)/C39,"") | H39: =IF(N(C39)=0,"",IF(D39/C39>=0.9,"VENCEU","REPETE"))
F40: =IFERROR(D40/C40,"") | G40: =IFERROR((D40-E40)/C40,"") | H40: =IF(N(C40)=0,"",IF(D40/C40>=0.9,"VENCEU","REPETE"))
F41: =IFERROR(D41/C41,"") | G41: =IFERROR((D41-E41)/C41,"") | H41: =IF(N(C41)=0,"",IF(D41/C41>=0.9,"VENCEU","REPETE"))
F42: =IFERROR(D42/C42,"") | G42: =IFERROR((D42-E42)/C42,"") | H42: =IF(N(C42)=0,"",IF(D42/C42>=0.9,"VENCEU","REPETE"))
F43: =IFERROR(D43/C43,"") | G43: =IFERROR((D43-E43)/C43,"") | H43: =IF(N(C43)=0,"",IF(D43/C43>=0.9,"VENCEU","REPETE"))
F44: =IFERROR(D44/C44,"") | G44: =IFERROR((D44-E44)/C44,"") | H44: =IF(N(C44)=0,"",IF(D44/C44>=0.9,"VENCEU","REPETE"))
...

Sheet RLM
A1: Raciocínio Lógico e Matemática Financeira | E1: Bloco P1 · Sábado · 7 tópicos · 10 itens estimados do edital
A2: Escreva o nome de cada filtro na linha 4 e marque X nas linhas do que ele sorteia. Amarelo = você preenche. Aula entre parênteses = a aula cobre o tópico, mas o rótulo dela não cita esse subtópico.
D4: Nome do filtro no Gran → | M4: GERAL N2
D5: Este filtro venceu (≥90%)? →
A7: Nº | B7: Tópico e subtópico do edital | C7: Peso | D7: Aula Gran | E7: F1 | F7: F2 | G7: F3 | H7: F4 | I7: F5 | J7: F6 | K7: F7 | L7: F8 | M7: GERAL N2
A8: 1 | B8: Estruturas lógicas | C8: 1 | D8: 1
A9: 2 | B9: Lógica de argumentação | C9: 1 | D9: 1
B10: 2.1 analogias, inferências, deduções e conclusões | D10: 1
A11: 3 | B11: Lógica sentencial (ou proposicional) | C11: 3 | D11: 1
B12: 3.1 proposições simples e compostas | D12: 1
B13: 3.2 tabelas-verdade | D13: 1
B14: 3.3 equivalências | D14: 1
B15: 3.4 leis de De Morgan | D15: 1
B16: 3.5 diagramas lógicos | D16: 1
A17: 4 | B17: Lógica de primeira ordem | C17: 1 | D17: 1
A18: 5 | B18: Princípios de contagem e probabilidade | C18: 1 | D18: 2
A19: 6 | B19: Operações com conjuntos | C19: 1 | D19: 2
A20: 7 | B20: Matemática financeira | C20: 2 | D20: 3
B21: 7.1 razão e proporção, porcentagem, juros simples e compostos, taxas de juros (nominal, efetiva, equivalente), sistemas de amortização e fluxo de caixa | D21: 3
A24: REGISTRO DOS SIMULADOS DESTA MATÉRIA
A25: Filtro | B25: Data | C25: Total | D25: Acertos | E25: Erros | F25: % Bruto | G25: % Líquido | H25: Veredito
A26: exemplo — apague ou ignore | B26: 15/09/2026 | C26: 20 | D26: 18 | E26: 2 | F26: =IFERROR(D26/C26,"") | G26: =IFERROR((D26-E26)/C26,"") | H26: =IF(N(C26)=0,"",IF(D26/C26>=0.9,"VENCEU","REPETE"))
F27: =IFERROR(D27/C27,"") | G27: =IFERROR((D27-E27)/C27,"") | H27: =IF(N(C27)=0,"",IF(D27/C27>=0.9,"VENCEU","REPETE"))
F28: =IFERROR(D28/C28,"") | G28: =IFERROR((D28-E28)/C28,"") | H28: =IF(N(C28)=0,"",IF(D28/C28>=0.9,"VENCEU","REPETE"))
F29: =IFERROR(D29/C29,"") | G29: =IFERROR((D29-E29)/C29,"") | H29: =IF(N(C29)=0,"",IF(D29/C29>=0.9,"VENCEU","REPETE"))
F30: =IFERROR(D30/C30,"") | G30: =IFERROR((D30-E30)/C30,"") | H30: =IF(N(C30)=0,"",IF(D30/C30>=0.9,"VENCEU","REPETE"))
F31: =IFERROR(D31/C31,"") | G31: =IFERROR((D31-E31)/C31,"") | H31: =IF(N(C31)=0,"",IF(D31/C31>=0.9,"VENCEU","REPETE"))
F32: =IFERROR(D32/C32,"") | G32: =IFERROR((D32-E32)/C32,"") | H32: =IF(N(C32)=0,"",IF(D32/C32>=0.9,"VENCEU","REPETE"))
F33: =IFERROR(D33/C33,"") | G33: =IFERROR((D33-E33)/C33,"") | H33: =IF(N(C33)=0,"",IF(D33/C33>=0.9,"VENCEU","REPETE"))
F34: =IFERROR(D34/C34,"") | G34: =IFERROR((D34-E34)/C34,"") | H34: =IF(N(C34)=0,"",IF(D34/C34>=0.9,"VENCEU","REPETE"))
F35: =IFERROR(D35/C35,"") | G35: =IFERROR((D35-E35)/C35,"") | H35: =IF(N(C35)=0,"",IF(D35/C35>=0.9,"VENCEU","REPETE"))
F36: =IFERROR(D36/C36,"") | G36: =IFERROR((D36-E36)/C36,"") | H36: =IF(N(C36)=0,"",IF(D36/C36>=0.9,"VENCEU","REPETE"))
F37: =IFERROR(D37/C37,"") | G37: =IFERROR((D37-E37)/C37,"") | H37: =IF(N(C37)=0,"",IF(D37/C37>=0.9,"VENCEU","REPETE"))
F38: =IFERROR(D38/C38,"") | G38: =IFERROR((D38-E38)/C38,"") | H38: =IF(N(C38)=0,"",IF(D38/C38>=0.9,"VENCEU","REPETE"))
... F46: =IFERROR(D46/C46,"") | G46: =IFERROR((D46-E46)/C46,"") | H46: =IF(N(C46)=0,"",IF(D46/C46>=0.9,"VENCEU","REPETE"))

Sheet DF e Mulheres
A1: Conhecimentos do Distrito Federal e Política para Mulheres | E1: Bloco P1 · Sábado · 3 tópicos · 4 itens estimados do edital
A2: Escreva o nome de cada filtro na linha 4 e marque X nas linhas do que ele sorteia. Amarelo = você preenche. Aula entre parênteses = a aula cobre o tópico, mas o rótulo dela não cita esse subtópico.
D4: Nome do filtro no Gran → | M4: GERAL N2
D5: Este filtro venceu (≥90%)? →
A7: Nº | B7: Tópico e subtópico do edital | C7: Peso | D7: Aula Gran | E7: F1 | F7: F2 | G7: F3 | H7: F4 | I7: F5 | J7: F6 | K7: F7 | L7: F8 | M7: GERAL N2
A8: 1 | B8: Domínio de tópicos atuais e relevantes acerca da realidade étnica, social, histórica, geográfica, cultural, política e econômica do Distrito Federal e da Região Integrada de Desenvolvimento do Distrito Federal e Entorno (RIDE) (Lei Complementar federal nº 94/1998 e Decreto federal nº 7.469/2011) | C8: 2 | D8: 2
A9: 2 | B9: Plano Distrital de Política para Mulheres (2020–2023) | C9: 1 | D9: 3
A10: 3 | B10: Lei Federal nº 11.340/2006 – Lei Maria da Penha | C10: 1 | D10: 4
A13: REGISTRO DOS SIMULADOS DESTA MATÉRIA
A14: Filtro | B14: Data | C14: Total | D14: Acertos | E14: Erros | F14: % Bruto | G14: % Líquido | H14: Veredito
A15: exemplo — apague ou ignore | B15: 15/09/2026 | C15: 20 | D15: 18 | E15: 2 | F15: =IFERROR(D15/C15,"") | G15: =IFERROR((D15-E15)/C15,"") | H15: =IF(N(C15)=0,"",IF(D15/C15>=0.9,"VENCEU","REPETE"))
F16: =IFERROR(D16/C16,"") | G16: =IFERROR((D16-E16)/C16,"") | H16: =IF(N(C16)=0,"",IF(D16/C16>=0.9,"VENCEU","REPETE"))
F17: =IFERROR(D17/C17,"") | G17: =IFERROR((D17-E17)/C17,"") | H17: =IF(N(C17)=0,"",IF(D17/C17>=0.9,"VENCEU","REPETE"))
F18: =IFERROR(D18/C18,"") | G18: =IFERROR((D18-E18)/C18,"") | H18: =IF(N(C18)=0,"",IF(D18/C18>=0.9,"VENCEU","REPETE"))
F19: =IFERROR(D19/C19,"") | G19: =IFERROR((D19-E19)/C19,"") | H19: =IF(N(C19)=0,"",IF(D19/C19>=0.9,"VENCEU","REPETE"))
F20: =IFERROR(D20/C20,"") | G20: =IFERROR((D20-E20)/C20,"") | H20: =IF(N(C20)=0,"",IF(D20/C20>=0.9,"VENCEU","REPETE"))
F21: =IFERROR(D21/C21,"") | G21: =IFERROR((D21-E21)/C21,"") | H21: =IF(N(C21)=0,"",IF(D21/C21>=0.9,"VENCEU","REPETE"))
F22: =IFERROR(D22/C22,"") | G22: =IFERROR((D22-E22)/C22,"") | H22: =IF(N(C22)=0,"",IF(D22/C22>=0.9,"VENCEU","REPETE"))
F23: =IFERROR(D23/C23,"") | G23: =IFERROR((D23-E23)/C23,"") | H23: =IF(N(C23)=0,"",IF(D23/C23>=0.9,"VENCEU","REPETE"))
F24: =IFERROR(D24/C24,"") | G24: =IFERROR((D24-E24)/C24,"") | H24: =IF(N(C24)=0,"",IF(D24/C24>=0.9,"VENCEU","REPETE"))
F25: =IFERROR(D25/C25,"") | G25: =IFERROR((D25-E25)/C25,"") | H25: =IF(N(C25)=0,"",IF(D25/C25>=0.9,"VENCEU","REPETE"))
F26: =IFERROR(D26/C26,"") | G26: =IFERROR((D26-E26)/C26,"") | H26: =IF(N(C26)=0,"",IF(D26/C26>=0.9,"VENCEU","REPETE"))
F27: =IFERROR(D27/C27,"") | G27: =IFERROR((D27-E27)/C27,"") | H27: =IF(N(C27)=0,"",IF(D27/C27>=0.9,"VENCEU","REPETE"))
... F35: =IFERROR(D35/C35,"") | G35: =IFERROR((D35-E35)/C35,"") | H35: =IF(N(C35)=0,"",IF(D35/C35>=0.9,"VENCEU","REPETE"))

Sheet Primeiros Socorros
A1: Noções de Primeiros Socorros | E1: Bloco P1 · Sábado · 1 tópicos · 3 itens estimados do edital
A2: Escreva o nome de cada filtro na linha 4 e marque X nas linhas do que ele sorteia. Amarelo = você preenche. Aula entre parênteses = a aula cobre o tópico, mas o rótulo dela não cita esse subtópico.
D4: Nome do filtro no Gran → | M4: GERAL N2
D5: Este filtro venceu (≥90%)? →
A7: Nº | B7: Tópico e subtópico do edital | C7: Peso | D7: Aula Gran | E7: F1 | F7: F2 | G7: F3 | H7: F4 | I7: F5 | J7: F6 | K7: F7 | L7: F8 | M7: GERAL N2
A8: 1 | B8: Cuidados iniciais com a vítima, reconhecimento de situações de urgência e emergência, acionamento do socorro especializado e condutas básicas em casos de engasgo, sangramento, fratura, queimadura, desmaio, convulsão e intoxicação | C8: 3 | D8: 2
B9: Avaliação da cena, segurança do socorrista e avaliação da vítima (subdivisão sugerida)
B10: Reconhecimento de urgência e emergência e acionamento do socorro (SAMU 192 / Bombeiros 193) (subdivisão sugerida)
B11: Engasgo (obstrução de via aérea) e manobra de desobstrução (subdivisão sugerida)
B12: Sangramento e controle de hemorragia (subdivisão sugerida)
B13: Fratura e imobilização (subdivisão sugerida)
B14: Queimadura (subdivisão sugerida)
B15: Desmaio (subdivisão sugerida)
B16: Convulsão (subdivisão sugerida)
B17: Intoxicação (subdivisão sugerida)
A20: REGISTRO DOS SIMULADOS DESTA MATÉRIA
A21: Filtro | B21: Data | C21: Total | D21: Acertos | E21: Erros | F21: % Bruto | G21: % Líquido | H21: Veredito
A22: exemplo — apague ou ignore | B22: 15/09/2026 | C22: 20 | D22: 18 | E22: 2 | F22: =IFERROR(D22/C22,"") | G22: =IFERROR((D22-E22)/C22,"") | H22: =IF(N(C22)=0,"",IF(D22/C22>=0.9,"VENCEU","REPETE"))
F23: =IFERROR(D23/C23,"") | G23: =IFERROR((D23-E23)/C23,"") | H23: =IF(N(C23)=0,"",IF(D23/C23>=0.9,"VENCEU","REPETE"))
F24: =IFERROR(D24/C24,"") | G24: =IFERROR((D24-E24)/C24,"") | H24: =IF(N(C24)=0,"",IF(D24/C24>=0.9,"VENCEU","REPETE"))
F25: =IFERROR(D25/C25,"") | G25: =IFERROR((D25-E25)/C25,"") | H25: =IF(N(C25)=0,"",IF(D25/C25>=0.9,"VENCEU","REPETE"))
F26: =IFERROR(D26/C26,"") | G26: =IFERROR((D26-E26)/C26,"") | H26: =IF(N(C26)=0,"",IF(D26/C26>=0.9,"VENCEU","REPETE"))
F27: =IFERROR(D27/C27,"") | G27: =IFERROR((D27-E27)/C27,"") | H27: =IF(N(C27)=0,"",IF(D27/C27>=0.9,"VENCEU","REPETE"))
F28: =IFERROR(D28/C28,"") | G28: =IFERROR((D28-E28)/C28,"") | H28: =IF(N(C28)=0,"",IF(D28/C28>=0.9,"VENCEU","REPETE"))
F29: =IFERROR(D29/C29,"") | G29: =IFERROR((D29-E29)/C29,"") | H29: =IF(N(C29)=0,"",IF(D29/C29>=0.9,"VENCEU","REPETE"))
F30: =IFERROR(D30/C30,"") | G30: =IFERROR((D30-E30)/C30,"") | H30: =IF(N(C30)=0,"",IF(D30/C30>=0.9,"VENCEU","REPETE"))
F31: =IFERROR(D31/C31,"") | G31: =IFERROR((D31-E31)/C31,"") | H31: =IF(N(C31)=0,"",IF(D31/C31>=0.9,"VENCEU","REPETE"))
F32: =IFERROR(D32/C32,"") | G32: =IFERROR((D32-E32)/C32,"") | H32: =IF(N(C32)=0,"",IF(D32/C32>=0.9,"VENCEU","REPETE"))
F33: =IFERROR(D33/C33,"") | G33: =IFERROR((D33-E33)/C33,"") | H33: =IF(N(C33)=0,"",IF(D33/C33>=0.9,"VENCEU","REPETE"))
F34: =IFERROR(D34/C34,"") | G34: =IFERROR((D34-E34)/C34,"") | H34: =IF(N(C34)=0,"",IF(D34/C34>=0.9,"VENCEU","REPETE"))
... F42: =IFERROR(D42/C42,"") | G42: =IFERROR((D42-E42)/C42,"") | H42: =IF(N(C42)=0,"",IF(D42/C42>=0.9,"VENCEU","REPETE"))

Sheet Aulas do Gran
A1: Aulas do curso do Gran e o que cada uma cobre do edital
A2: Extraído do rótulo de cada aula. O curso fatia e reordena o programa, então a numeração das aulas não segue a do edital.
A4: Matéria | B4: Aula | C4: O que a aula cobre | D4: Tópicos do edital
A5: Administração Financeira e Orçamentária | B5: 1 | C5: 1 Orcamento publico. 1.1 Conceito. 1.2 Tecnicas orcamentarias | D5: 1
A6: Administração Financeira e Orçamentária | B6: 2 | C6: 2.2 PPA. 2.3 LDO. 2.4 LOA | D6: 2
A7: Administração Financeira e Orçamentária | B7: 3 | C7: 1.4 Ciclo orcamentario. 1.5 Processo orcamentario | D7: 1
A8: Administração Financeira e Orçamentária | B8: 4 | C8: 2.1 Sistema de planejamento e orcamento federal. 2.5 Processo de orcamentacao | D8: 2
A9: Administração Financeira e Orçamentária | B9: 5 | C9: 2.8 Creditos ordinarios e adicionais | D9: 2
A10: Administração Financeira e Orçamentária | B10: 6 | C10: 1.3 Principios orcamentarios | D10: 1
A11: Administração Financeira e Orçamentária | B11: 7 | C11: 4 Receita publica, estagios, fontes e divida ativa | D11: 4
A12: Administração Financeira e Orçamentária | B12: 8 | C12: 5 Despesa publica. 2.6 Classificacoes. 2.7 Estrutura programatica. 7 Lei 4.320/1964 | D12: 5, 2, 7
A13: Administração Financeira e Orçamentária | B13: 9 | C13: 3 Programacao e execucao orcamentaria e financeira | D13: 3
A14: Administração Financeira e Orçamentária | B14: 10 | C14: 6 LRF. 5.5 Divida flutuante e fundada. 8 Transferencias voluntarias | D14: 6, 5, 8
A15: Administração Financeira e Orçamentária | B15: 11 | C15: 9 Decreto distrital 32.598/2010 | D15: 9
A16: Noções de Direito Tributário | B16: 1 | C16: Apresentacao da disciplina | D16: —
... A115: Noções de Primeiros Socorros | B115: 2 | C115: 1 Cuidados iniciais, urgencia e emergencia, condutas basicas | D115: 1
